{
 "cells": [
  {
   "cell_type": "markdown",
   "metadata": {},
   "source": [
    "# Домашнеие задание № 7"
   ]
  },
  {
   "attachments": {},
   "cell_type": "markdown",
   "metadata": {},
   "source": [
    "1. Попробуйте обучить нейронную сеть GRU/LSTM для предсказания сентимента сообщений с твитера на примере    \n",
    "https://www.kaggle.com/datasets/arkhoshghalb/twitter-sentiment-analysis-hatred-speech\n",
    "\n",
    "2. Опишите, какой результат вы получили? Что помогло вам улучшить ее точность?  \n",
    "\n",
    "У кого нет возможности работать через каггл (нет верификации), то можете данные взять по ссылке: https://disk.yandex.ru/d/LV1cYS1orMyRWA"
   ]
  },
  {
   "cell_type": "code",
   "execution_count": 3,
   "metadata": {},
   "outputs": [],
   "source": [
    "import pandas as pd\n",
    "from string import punctuation\n",
    "from stop_words import get_stop_words\n",
    "from pymorphy2 import MorphAnalyzer\n",
    "import re"
   ]
  },
  {
   "cell_type": "code",
   "execution_count": 12,
   "metadata": {},
   "outputs": [
    {
     "name": "stderr",
     "output_type": "stream",
     "text": [
      "\"wget\" �� ���� ����७��� ��� ���譥�\n",
      "��������, �ᯮ��塞�� �ணࠬ��� ��� ������ 䠩���.\n"
     ]
    }
   ],
   "source": [
    "!wget 'https://www.kaggle.com/datasets/arkhoshghalb/twitter-sentiment-analysis-hatred-speech' -O data.zip\n",
    "\n",
    "#при вызове указанной слыллки выдает абракодабру "
   ]
  },
  {
   "cell_type": "code",
   "execution_count": 5,
   "metadata": {},
   "outputs": [
    {
     "name": "stderr",
     "output_type": "stream",
     "text": [
      "\"unzip\" �� ���� ����७��� ��� ���譥�\n",
      "��������, �ᯮ��塞�� �ணࠬ��� ��� ������ 䠩���.\n"
     ]
    }
   ],
   "source": [
    "!unzip data.zip"
   ]
  },
  {
   "cell_type": "code",
   "execution_count": 10,
   "metadata": {},
   "outputs": [
    {
     "name": "stdout",
     "output_type": "stream",
     "text": [
      "Unexpected exception formatting exception. Falling back to standard exception\n"
     ]
    },
    {
     "name": "stderr",
     "output_type": "stream",
     "text": [
      "Traceback (most recent call last):\n",
      "  File \"c:\\Users\\azhur\\AppData\\Local\\Programs\\Python\\Python310\\lib\\site-packages\\IPython\\core\\interactiveshell.py\", line 3398, in run_code\n",
      "    exec(code_obj, self.user_global_ns, self.user_ns)\n",
      "  File \"C:\\Users\\azhur\\AppData\\Local\\Temp\\ipykernel_34128\\369594164.py\", line 3, in <cell line: 3>\n",
      "    df_train = pd.read_csv(\"train.csv\")\n",
      "  File \"c:\\Users\\azhur\\AppData\\Local\\Programs\\Python\\Python310\\lib\\site-packages\\pandas\\util\\_decorators.py\", line 311, in wrapper\n",
      "    return func(*args, **kwargs)\n",
      "  File \"c:\\Users\\azhur\\AppData\\Local\\Programs\\Python\\Python310\\lib\\site-packages\\pandas\\io\\parsers\\readers.py\", line 680, in read_csv\n",
      "    return _read(filepath_or_buffer, kwds)\n",
      "  File \"c:\\Users\\azhur\\AppData\\Local\\Programs\\Python\\Python310\\lib\\site-packages\\pandas\\io\\parsers\\readers.py\", line 575, in _read\n",
      "    parser = TextFileReader(filepath_or_buffer, **kwds)\n",
      "  File \"c:\\Users\\azhur\\AppData\\Local\\Programs\\Python\\Python310\\lib\\site-packages\\pandas\\io\\parsers\\readers.py\", line 933, in __init__\n",
      "    self._engine = self._make_engine(f, self.engine)\n",
      "  File \"c:\\Users\\azhur\\AppData\\Local\\Programs\\Python\\Python310\\lib\\site-packages\\pandas\\io\\parsers\\readers.py\", line 1217, in _make_engine\n",
      "    self.handles = get_handle(  # type: ignore[call-overload]\n",
      "  File \"c:\\Users\\azhur\\AppData\\Local\\Programs\\Python\\Python310\\lib\\site-packages\\pandas\\io\\common.py\", line 789, in get_handle\n",
      "    handle = open(\n",
      "FileNotFoundError: [Errno 2] No such file or directory: 'train.csv'\n",
      "\n",
      "During handling of the above exception, another exception occurred:\n",
      "\n",
      "Traceback (most recent call last):\n",
      "  File \"c:\\Users\\azhur\\AppData\\Local\\Programs\\Python\\Python310\\lib\\site-packages\\IPython\\core\\interactiveshell.py\", line 1993, in showtraceback\n",
      "    stb = self.InteractiveTB.structured_traceback(\n",
      "  File \"c:\\Users\\azhur\\AppData\\Local\\Programs\\Python\\Python310\\lib\\site-packages\\IPython\\core\\ultratb.py\", line 1118, in structured_traceback\n",
      "    return FormattedTB.structured_traceback(\n",
      "  File \"c:\\Users\\azhur\\AppData\\Local\\Programs\\Python\\Python310\\lib\\site-packages\\IPython\\core\\ultratb.py\", line 1012, in structured_traceback\n",
      "    return VerboseTB.structured_traceback(\n",
      "  File \"c:\\Users\\azhur\\AppData\\Local\\Programs\\Python\\Python310\\lib\\site-packages\\IPython\\core\\ultratb.py\", line 865, in structured_traceback\n",
      "    formatted_exception = self.format_exception_as_a_whole(etype, evalue, etb, number_of_lines_of_context,\n",
      "  File \"c:\\Users\\azhur\\AppData\\Local\\Programs\\Python\\Python310\\lib\\site-packages\\IPython\\core\\ultratb.py\", line 799, in format_exception_as_a_whole\n",
      "    self.get_records(etb, number_of_lines_of_context, tb_offset) if etb else []\n",
      "  File \"c:\\Users\\azhur\\AppData\\Local\\Programs\\Python\\Python310\\lib\\site-packages\\IPython\\core\\ultratb.py\", line 845, in get_records\n",
      "    style = stack_data.style_with_executing_node(style, \"bg:ansiyellow\")\n",
      "  File \"c:\\Users\\azhur\\AppData\\Local\\Programs\\Python\\Python310\\lib\\site-packages\\stack_data\\core.py\", line 424, in style_with_executing_node\n",
      "    class NewStyle(style):\n",
      "  File \"c:\\Users\\azhur\\AppData\\Local\\Programs\\Python\\Python310\\lib\\site-packages\\pygments\\style.py\", line 91, in __new__\n",
      "    ndef[4] = colorformat(styledef[3:])\n",
      "  File \"c:\\Users\\azhur\\AppData\\Local\\Programs\\Python\\Python310\\lib\\site-packages\\pygments\\style.py\", line 58, in colorformat\n",
      "    assert False, \"wrong color format %r\" % text\n",
      "AssertionError: wrong color format 'ansiyellow'\n"
     ]
    }
   ],
   "source": [
    "import pandas as pd\n",
    "\n",
    "df_train = pd.read_csv(\"train.csv\")\n",
    "df_val = pd.read_csv(\"val.csv\")"
   ]
  },
  {
   "cell_type": "code",
   "execution_count": 13,
   "metadata": {},
   "outputs": [
    {
     "name": "stdout",
     "output_type": "stream",
     "text": [
      "Unexpected exception formatting exception. Falling back to standard exception\n"
     ]
    },
    {
     "name": "stderr",
     "output_type": "stream",
     "text": [
      "Traceback (most recent call last):\n",
      "  File \"c:\\Users\\azhur\\AppData\\Local\\Programs\\Python\\Python310\\lib\\site-packages\\IPython\\core\\interactiveshell.py\", line 3398, in run_code\n",
      "    exec(code_obj, self.user_global_ns, self.user_ns)\n",
      "  File \"C:\\Users\\azhur\\AppData\\Local\\Temp\\ipykernel_34128\\3489078649.py\", line 1, in <cell line: 1>\n",
      "    df_train.head()\n",
      "NameError: name 'df_train' is not defined\n",
      "\n",
      "During handling of the above exception, another exception occurred:\n",
      "\n",
      "Traceback (most recent call last):\n",
      "  File \"c:\\Users\\azhur\\AppData\\Local\\Programs\\Python\\Python310\\lib\\site-packages\\IPython\\core\\interactiveshell.py\", line 1993, in showtraceback\n",
      "    stb = self.InteractiveTB.structured_traceback(\n",
      "  File \"c:\\Users\\azhur\\AppData\\Local\\Programs\\Python\\Python310\\lib\\site-packages\\IPython\\core\\ultratb.py\", line 1118, in structured_traceback\n",
      "    return FormattedTB.structured_traceback(\n",
      "  File \"c:\\Users\\azhur\\AppData\\Local\\Programs\\Python\\Python310\\lib\\site-packages\\IPython\\core\\ultratb.py\", line 1012, in structured_traceback\n",
      "    return VerboseTB.structured_traceback(\n",
      "  File \"c:\\Users\\azhur\\AppData\\Local\\Programs\\Python\\Python310\\lib\\site-packages\\IPython\\core\\ultratb.py\", line 865, in structured_traceback\n",
      "    formatted_exception = self.format_exception_as_a_whole(etype, evalue, etb, number_of_lines_of_context,\n",
      "  File \"c:\\Users\\azhur\\AppData\\Local\\Programs\\Python\\Python310\\lib\\site-packages\\IPython\\core\\ultratb.py\", line 799, in format_exception_as_a_whole\n",
      "    self.get_records(etb, number_of_lines_of_context, tb_offset) if etb else []\n",
      "  File \"c:\\Users\\azhur\\AppData\\Local\\Programs\\Python\\Python310\\lib\\site-packages\\IPython\\core\\ultratb.py\", line 845, in get_records\n",
      "    style = stack_data.style_with_executing_node(style, \"bg:ansiyellow\")\n",
      "  File \"c:\\Users\\azhur\\AppData\\Local\\Programs\\Python\\Python310\\lib\\site-packages\\stack_data\\core.py\", line 424, in style_with_executing_node\n",
      "    class NewStyle(style):\n",
      "  File \"c:\\Users\\azhur\\AppData\\Local\\Programs\\Python\\Python310\\lib\\site-packages\\pygments\\style.py\", line 91, in __new__\n",
      "    ndef[4] = colorformat(styledef[3:])\n",
      "  File \"c:\\Users\\azhur\\AppData\\Local\\Programs\\Python\\Python310\\lib\\site-packages\\pygments\\style.py\", line 58, in colorformat\n",
      "    assert False, \"wrong color format %r\" % text\n",
      "AssertionError: wrong color format 'ansiyellow'\n"
     ]
    }
   ],
   "source": [
    "df_train.head()"
   ]
  },
  {
   "cell_type": "code",
   "execution_count": 14,
   "metadata": {},
   "outputs": [],
   "source": [
    "sw = set(get_stop_words(\"ru\"))\n",
    "puncts = set(punctuation)\n",
    "morpher = MorphAnalyzer()\n",
    "\n",
    "\n",
    "def preprocess_text(txt):\n",
    "    txt = str(txt)\n",
    "    txt = \"\".join(c for c in txt if c not in puncts)\n",
    "    txt = txt.lower()\n",
    "    txt = re.sub(\"не\\s\", \"не\", txt)\n",
    "    txt = [morpher.parse(word)[0].normal_form for word in txt.split() if word not in sw]\n",
    "    return \" \".join(txt)"
   ]
  },
  {
   "cell_type": "code",
   "execution_count": 15,
   "metadata": {},
   "outputs": [
    {
     "name": "stdout",
     "output_type": "stream",
     "text": [
      "Unexpected exception formatting exception. Falling back to standard exception\n"
     ]
    },
    {
     "name": "stderr",
     "output_type": "stream",
     "text": [
      "Traceback (most recent call last):\n",
      "  File \"c:\\Users\\azhur\\AppData\\Local\\Programs\\Python\\Python310\\lib\\site-packages\\IPython\\core\\interactiveshell.py\", line 3398, in run_code\n",
      "    exec(code_obj, self.user_global_ns, self.user_ns)\n",
      "  File \"C:\\Users\\azhur\\AppData\\Local\\Temp\\ipykernel_34128\\574241269.py\", line 4, in <cell line: 4>\n",
      "    df_train['text'] = df_train['text'].progress_apply(preprocess_text)\n",
      "NameError: name 'df_train' is not defined\n",
      "\n",
      "During handling of the above exception, another exception occurred:\n",
      "\n",
      "Traceback (most recent call last):\n",
      "  File \"c:\\Users\\azhur\\AppData\\Local\\Programs\\Python\\Python310\\lib\\site-packages\\IPython\\core\\interactiveshell.py\", line 1993, in showtraceback\n",
      "    stb = self.InteractiveTB.structured_traceback(\n",
      "  File \"c:\\Users\\azhur\\AppData\\Local\\Programs\\Python\\Python310\\lib\\site-packages\\IPython\\core\\ultratb.py\", line 1118, in structured_traceback\n",
      "    return FormattedTB.structured_traceback(\n",
      "  File \"c:\\Users\\azhur\\AppData\\Local\\Programs\\Python\\Python310\\lib\\site-packages\\IPython\\core\\ultratb.py\", line 1012, in structured_traceback\n",
      "    return VerboseTB.structured_traceback(\n",
      "  File \"c:\\Users\\azhur\\AppData\\Local\\Programs\\Python\\Python310\\lib\\site-packages\\IPython\\core\\ultratb.py\", line 865, in structured_traceback\n",
      "    formatted_exception = self.format_exception_as_a_whole(etype, evalue, etb, number_of_lines_of_context,\n",
      "  File \"c:\\Users\\azhur\\AppData\\Local\\Programs\\Python\\Python310\\lib\\site-packages\\IPython\\core\\ultratb.py\", line 799, in format_exception_as_a_whole\n",
      "    self.get_records(etb, number_of_lines_of_context, tb_offset) if etb else []\n",
      "  File \"c:\\Users\\azhur\\AppData\\Local\\Programs\\Python\\Python310\\lib\\site-packages\\IPython\\core\\ultratb.py\", line 845, in get_records\n",
      "    style = stack_data.style_with_executing_node(style, \"bg:ansiyellow\")\n",
      "  File \"c:\\Users\\azhur\\AppData\\Local\\Programs\\Python\\Python310\\lib\\site-packages\\stack_data\\core.py\", line 424, in style_with_executing_node\n",
      "    class NewStyle(style):\n",
      "  File \"c:\\Users\\azhur\\AppData\\Local\\Programs\\Python\\Python310\\lib\\site-packages\\pygments\\style.py\", line 91, in __new__\n",
      "    ndef[4] = colorformat(styledef[3:])\n",
      "  File \"c:\\Users\\azhur\\AppData\\Local\\Programs\\Python\\Python310\\lib\\site-packages\\pygments\\style.py\", line 58, in colorformat\n",
      "    assert False, \"wrong color format %r\" % text\n",
      "AssertionError: wrong color format 'ansiyellow'\n"
     ]
    }
   ],
   "source": [
    "from tqdm import tqdm \n",
    "tqdm.pandas()\n",
    "\n",
    "df_train['text'] = df_train['text'].progress_apply(preprocess_text)\n",
    "df_val['text'] = df_val['text'].progress_apply(preprocess_text)"
   ]
  },
  {
   "cell_type": "code",
   "execution_count": 16,
   "metadata": {},
   "outputs": [
    {
     "name": "stdout",
     "output_type": "stream",
     "text": [
      "Unexpected exception formatting exception. Falling back to standard exception\n"
     ]
    },
    {
     "name": "stderr",
     "output_type": "stream",
     "text": [
      "Traceback (most recent call last):\n",
      "  File \"c:\\Users\\azhur\\AppData\\Local\\Programs\\Python\\Python310\\lib\\site-packages\\IPython\\core\\interactiveshell.py\", line 3398, in run_code\n",
      "    exec(code_obj, self.user_global_ns, self.user_ns)\n",
      "  File \"C:\\Users\\azhur\\AppData\\Local\\Temp\\ipykernel_34128\\774163316.py\", line 1, in <cell line: 1>\n",
      "    train_corpus = \" \".join(df_train[\"text\"])\n",
      "NameError: name 'df_train' is not defined\n",
      "\n",
      "During handling of the above exception, another exception occurred:\n",
      "\n",
      "Traceback (most recent call last):\n",
      "  File \"c:\\Users\\azhur\\AppData\\Local\\Programs\\Python\\Python310\\lib\\site-packages\\IPython\\core\\interactiveshell.py\", line 1993, in showtraceback\n",
      "    stb = self.InteractiveTB.structured_traceback(\n",
      "  File \"c:\\Users\\azhur\\AppData\\Local\\Programs\\Python\\Python310\\lib\\site-packages\\IPython\\core\\ultratb.py\", line 1118, in structured_traceback\n",
      "    return FormattedTB.structured_traceback(\n",
      "  File \"c:\\Users\\azhur\\AppData\\Local\\Programs\\Python\\Python310\\lib\\site-packages\\IPython\\core\\ultratb.py\", line 1012, in structured_traceback\n",
      "    return VerboseTB.structured_traceback(\n",
      "  File \"c:\\Users\\azhur\\AppData\\Local\\Programs\\Python\\Python310\\lib\\site-packages\\IPython\\core\\ultratb.py\", line 865, in structured_traceback\n",
      "    formatted_exception = self.format_exception_as_a_whole(etype, evalue, etb, number_of_lines_of_context,\n",
      "  File \"c:\\Users\\azhur\\AppData\\Local\\Programs\\Python\\Python310\\lib\\site-packages\\IPython\\core\\ultratb.py\", line 799, in format_exception_as_a_whole\n",
      "    self.get_records(etb, number_of_lines_of_context, tb_offset) if etb else []\n",
      "  File \"c:\\Users\\azhur\\AppData\\Local\\Programs\\Python\\Python310\\lib\\site-packages\\IPython\\core\\ultratb.py\", line 845, in get_records\n",
      "    style = stack_data.style_with_executing_node(style, \"bg:ansiyellow\")\n",
      "  File \"c:\\Users\\azhur\\AppData\\Local\\Programs\\Python\\Python310\\lib\\site-packages\\stack_data\\core.py\", line 424, in style_with_executing_node\n",
      "    class NewStyle(style):\n",
      "  File \"c:\\Users\\azhur\\AppData\\Local\\Programs\\Python\\Python310\\lib\\site-packages\\pygments\\style.py\", line 91, in __new__\n",
      "    ndef[4] = colorformat(styledef[3:])\n",
      "  File \"c:\\Users\\azhur\\AppData\\Local\\Programs\\Python\\Python310\\lib\\site-packages\\pygments\\style.py\", line 58, in colorformat\n",
      "    assert False, \"wrong color format %r\" % text\n",
      "AssertionError: wrong color format 'ansiyellow'\n"
     ]
    }
   ],
   "source": [
    "train_corpus = \" \".join(df_train[\"text\"])\n",
    "train_corpus = train_corpus.lower()"
   ]
  },
  {
   "cell_type": "code",
   "execution_count": 17,
   "metadata": {},
   "outputs": [
    {
     "name": "stdout",
     "output_type": "stream",
     "text": [
      "Unexpected exception formatting exception. Falling back to standard exception\n"
     ]
    },
    {
     "name": "stderr",
     "output_type": "stream",
     "text": [
      "Traceback (most recent call last):\n",
      "  File \"c:\\Users\\azhur\\AppData\\Local\\Programs\\Python\\Python310\\lib\\site-packages\\IPython\\core\\interactiveshell.py\", line 3398, in run_code\n",
      "    exec(code_obj, self.user_global_ns, self.user_ns)\n",
      "  File \"C:\\Users\\azhur\\AppData\\Local\\Temp\\ipykernel_34128\\3501619943.py\", line 1, in <cell line: 1>\n",
      "    import nltk\n",
      "  File \"c:\\Users\\azhur\\AppData\\Local\\Programs\\Python\\Python310\\lib\\site-packages\\nltk\\__init__.py\", line 134, in <module>\n",
      "    from nltk.text import *\n",
      "  File \"c:\\Users\\azhur\\AppData\\Local\\Programs\\Python\\Python310\\lib\\site-packages\\nltk\\text.py\", line 26, in <module>\n",
      "    from nltk.lm import MLE\n",
      "  File \"c:\\Users\\azhur\\AppData\\Local\\Programs\\Python\\Python310\\lib\\site-packages\\nltk\\lm\\__init__.py\", line 222, in <module>\n",
      "    from nltk.lm.models import (\n",
      "  File \"c:\\Users\\azhur\\AppData\\Local\\Programs\\Python\\Python310\\lib\\site-packages\\nltk\\lm\\models.py\", line 12, in <module>\n",
      "    from nltk.lm.api import LanguageModel, Smoothing\n",
      "  File \"c:\\Users\\azhur\\AppData\\Local\\Programs\\Python\\Python310\\lib\\site-packages\\nltk\\lm\\api.py\", line 17, in <module>\n",
      "    from nltk.lm.counter import NgramCounter\n",
      "  File \"c:\\Users\\azhur\\AppData\\Local\\Programs\\Python\\Python310\\lib\\site-packages\\nltk\\lm\\counter.py\", line 15, in <module>\n",
      "    from collections import Sequence, defaultdict\n",
      "ImportError: cannot import name 'Sequence' from 'collections' (c:\\Users\\azhur\\AppData\\Local\\Programs\\Python\\Python310\\lib\\collections\\__init__.py)\n",
      "\n",
      "During handling of the above exception, another exception occurred:\n",
      "\n",
      "Traceback (most recent call last):\n",
      "  File \"c:\\Users\\azhur\\AppData\\Local\\Programs\\Python\\Python310\\lib\\site-packages\\IPython\\core\\interactiveshell.py\", line 1993, in showtraceback\n",
      "    stb = self.InteractiveTB.structured_traceback(\n",
      "  File \"c:\\Users\\azhur\\AppData\\Local\\Programs\\Python\\Python310\\lib\\site-packages\\IPython\\core\\ultratb.py\", line 1118, in structured_traceback\n",
      "    return FormattedTB.structured_traceback(\n",
      "  File \"c:\\Users\\azhur\\AppData\\Local\\Programs\\Python\\Python310\\lib\\site-packages\\IPython\\core\\ultratb.py\", line 1012, in structured_traceback\n",
      "    return VerboseTB.structured_traceback(\n",
      "  File \"c:\\Users\\azhur\\AppData\\Local\\Programs\\Python\\Python310\\lib\\site-packages\\IPython\\core\\ultratb.py\", line 865, in structured_traceback\n",
      "    formatted_exception = self.format_exception_as_a_whole(etype, evalue, etb, number_of_lines_of_context,\n",
      "  File \"c:\\Users\\azhur\\AppData\\Local\\Programs\\Python\\Python310\\lib\\site-packages\\IPython\\core\\ultratb.py\", line 799, in format_exception_as_a_whole\n",
      "    self.get_records(etb, number_of_lines_of_context, tb_offset) if etb else []\n",
      "  File \"c:\\Users\\azhur\\AppData\\Local\\Programs\\Python\\Python310\\lib\\site-packages\\IPython\\core\\ultratb.py\", line 845, in get_records\n",
      "    style = stack_data.style_with_executing_node(style, \"bg:ansiyellow\")\n",
      "  File \"c:\\Users\\azhur\\AppData\\Local\\Programs\\Python\\Python310\\lib\\site-packages\\stack_data\\core.py\", line 424, in style_with_executing_node\n",
      "    class NewStyle(style):\n",
      "  File \"c:\\Users\\azhur\\AppData\\Local\\Programs\\Python\\Python310\\lib\\site-packages\\pygments\\style.py\", line 91, in __new__\n",
      "    ndef[4] = colorformat(styledef[3:])\n",
      "  File \"c:\\Users\\azhur\\AppData\\Local\\Programs\\Python\\Python310\\lib\\site-packages\\pygments\\style.py\", line 58, in colorformat\n",
      "    assert False, \"wrong color format %r\" % text\n",
      "AssertionError: wrong color format 'ansiyellow'\n"
     ]
    }
   ],
   "source": [
    "import nltk\n",
    "from nltk.tokenize import word_tokenize\n",
    "nltk.download(\"punkt\")\n",
    "\n",
    "tokens = word_tokenize(train_corpus)"
   ]
  },
  {
   "attachments": {},
   "cell_type": "markdown",
   "metadata": {},
   "source": [
    "Фильтруем данные"
   ]
  },
  {
   "cell_type": "code",
   "execution_count": 18,
   "metadata": {},
   "outputs": [],
   "source": [
    "max_words = 2000\n",
    "max_len = 20\n",
    "num_classes = 1\n",
    "\n",
    "# Training\n",
    "epochs = 5\n",
    "batch_size = 512\n",
    "print_batch_n = 100"
   ]
  },
  {
   "cell_type": "code",
   "execution_count": 19,
   "metadata": {},
   "outputs": [
    {
     "name": "stdout",
     "output_type": "stream",
     "text": [
      "Unexpected exception formatting exception. Falling back to standard exception\n"
     ]
    },
    {
     "name": "stderr",
     "output_type": "stream",
     "text": [
      "Traceback (most recent call last):\n",
      "  File \"c:\\Users\\azhur\\AppData\\Local\\Programs\\Python\\Python310\\lib\\site-packages\\IPython\\core\\interactiveshell.py\", line 3398, in run_code\n",
      "    exec(code_obj, self.user_global_ns, self.user_ns)\n",
      "  File \"C:\\Users\\azhur\\AppData\\Local\\Temp\\ipykernel_34128\\3473883187.py\", line 1, in <cell line: 1>\n",
      "    tokens_filtered = [word for word in tokens if word.isalnum()]\n",
      "NameError: name 'tokens' is not defined\n",
      "\n",
      "During handling of the above exception, another exception occurred:\n",
      "\n",
      "Traceback (most recent call last):\n",
      "  File \"c:\\Users\\azhur\\AppData\\Local\\Programs\\Python\\Python310\\lib\\site-packages\\IPython\\core\\interactiveshell.py\", line 1993, in showtraceback\n",
      "    stb = self.InteractiveTB.structured_traceback(\n",
      "  File \"c:\\Users\\azhur\\AppData\\Local\\Programs\\Python\\Python310\\lib\\site-packages\\IPython\\core\\ultratb.py\", line 1118, in structured_traceback\n",
      "    return FormattedTB.structured_traceback(\n",
      "  File \"c:\\Users\\azhur\\AppData\\Local\\Programs\\Python\\Python310\\lib\\site-packages\\IPython\\core\\ultratb.py\", line 1012, in structured_traceback\n",
      "    return VerboseTB.structured_traceback(\n",
      "  File \"c:\\Users\\azhur\\AppData\\Local\\Programs\\Python\\Python310\\lib\\site-packages\\IPython\\core\\ultratb.py\", line 865, in structured_traceback\n",
      "    formatted_exception = self.format_exception_as_a_whole(etype, evalue, etb, number_of_lines_of_context,\n",
      "  File \"c:\\Users\\azhur\\AppData\\Local\\Programs\\Python\\Python310\\lib\\site-packages\\IPython\\core\\ultratb.py\", line 799, in format_exception_as_a_whole\n",
      "    self.get_records(etb, number_of_lines_of_context, tb_offset) if etb else []\n",
      "  File \"c:\\Users\\azhur\\AppData\\Local\\Programs\\Python\\Python310\\lib\\site-packages\\IPython\\core\\ultratb.py\", line 845, in get_records\n",
      "    style = stack_data.style_with_executing_node(style, \"bg:ansiyellow\")\n",
      "  File \"c:\\Users\\azhur\\AppData\\Local\\Programs\\Python\\Python310\\lib\\site-packages\\stack_data\\core.py\", line 424, in style_with_executing_node\n",
      "    class NewStyle(style):\n",
      "  File \"c:\\Users\\azhur\\AppData\\Local\\Programs\\Python\\Python310\\lib\\site-packages\\pygments\\style.py\", line 91, in __new__\n",
      "    ndef[4] = colorformat(styledef[3:])\n",
      "  File \"c:\\Users\\azhur\\AppData\\Local\\Programs\\Python\\Python310\\lib\\site-packages\\pygments\\style.py\", line 58, in colorformat\n",
      "    assert False, \"wrong color format %r\" % text\n",
      "AssertionError: wrong color format 'ansiyellow'\n"
     ]
    }
   ],
   "source": [
    "tokens_filtered = [word for word in tokens if word.isalnum()]"
   ]
  },
  {
   "cell_type": "code",
   "execution_count": 20,
   "metadata": {},
   "outputs": [
    {
     "name": "stdout",
     "output_type": "stream",
     "text": [
      "Unexpected exception formatting exception. Falling back to standard exception\n"
     ]
    },
    {
     "name": "stderr",
     "output_type": "stream",
     "text": [
      "Traceback (most recent call last):\n",
      "  File \"c:\\Users\\azhur\\AppData\\Local\\Programs\\Python\\Python310\\lib\\site-packages\\IPython\\core\\interactiveshell.py\", line 3398, in run_code\n",
      "    exec(code_obj, self.user_global_ns, self.user_ns)\n",
      "  File \"C:\\Users\\azhur\\AppData\\Local\\Temp\\ipykernel_34128\\1671398076.py\", line 3, in <cell line: 3>\n",
      "    dist = FreqDist(tokens_filtered)\n",
      "NameError: name 'tokens_filtered' is not defined\n",
      "\n",
      "During handling of the above exception, another exception occurred:\n",
      "\n",
      "Traceback (most recent call last):\n",
      "  File \"c:\\Users\\azhur\\AppData\\Local\\Programs\\Python\\Python310\\lib\\site-packages\\IPython\\core\\interactiveshell.py\", line 1993, in showtraceback\n",
      "    stb = self.InteractiveTB.structured_traceback(\n",
      "  File \"c:\\Users\\azhur\\AppData\\Local\\Programs\\Python\\Python310\\lib\\site-packages\\IPython\\core\\ultratb.py\", line 1118, in structured_traceback\n",
      "    return FormattedTB.structured_traceback(\n",
      "  File \"c:\\Users\\azhur\\AppData\\Local\\Programs\\Python\\Python310\\lib\\site-packages\\IPython\\core\\ultratb.py\", line 1012, in structured_traceback\n",
      "    return VerboseTB.structured_traceback(\n",
      "  File \"c:\\Users\\azhur\\AppData\\Local\\Programs\\Python\\Python310\\lib\\site-packages\\IPython\\core\\ultratb.py\", line 865, in structured_traceback\n",
      "    formatted_exception = self.format_exception_as_a_whole(etype, evalue, etb, number_of_lines_of_context,\n",
      "  File \"c:\\Users\\azhur\\AppData\\Local\\Programs\\Python\\Python310\\lib\\site-packages\\IPython\\core\\ultratb.py\", line 799, in format_exception_as_a_whole\n",
      "    self.get_records(etb, number_of_lines_of_context, tb_offset) if etb else []\n",
      "  File \"c:\\Users\\azhur\\AppData\\Local\\Programs\\Python\\Python310\\lib\\site-packages\\IPython\\core\\ultratb.py\", line 845, in get_records\n",
      "    style = stack_data.style_with_executing_node(style, \"bg:ansiyellow\")\n",
      "  File \"c:\\Users\\azhur\\AppData\\Local\\Programs\\Python\\Python310\\lib\\site-packages\\stack_data\\core.py\", line 424, in style_with_executing_node\n",
      "    class NewStyle(style):\n",
      "  File \"c:\\Users\\azhur\\AppData\\Local\\Programs\\Python\\Python310\\lib\\site-packages\\pygments\\style.py\", line 91, in __new__\n",
      "    ndef[4] = colorformat(styledef[3:])\n",
      "  File \"c:\\Users\\azhur\\AppData\\Local\\Programs\\Python\\Python310\\lib\\site-packages\\pygments\\style.py\", line 58, in colorformat\n",
      "    assert False, \"wrong color format %r\" % text\n",
      "AssertionError: wrong color format 'ansiyellow'\n"
     ]
    }
   ],
   "source": [
    "from nltk.probability import FreqDist\n",
    "\n",
    "dist = FreqDist(tokens_filtered)\n",
    "tokens_filtered_top = [pair[0] for pair in dist.most_common(max_words-1)]"
   ]
  },
  {
   "cell_type": "code",
   "execution_count": 21,
   "metadata": {},
   "outputs": [
    {
     "name": "stdout",
     "output_type": "stream",
     "text": [
      "Unexpected exception formatting exception. Falling back to standard exception\n"
     ]
    },
    {
     "name": "stderr",
     "output_type": "stream",
     "text": [
      "Traceback (most recent call last):\n",
      "  File \"c:\\Users\\azhur\\AppData\\Local\\Programs\\Python\\Python310\\lib\\site-packages\\IPython\\core\\interactiveshell.py\", line 3398, in run_code\n",
      "    exec(code_obj, self.user_global_ns, self.user_ns)\n",
      "  File \"C:\\Users\\azhur\\AppData\\Local\\Temp\\ipykernel_34128\\2919186333.py\", line 1, in <cell line: 1>\n",
      "    tokens_filtered_top[:10]\n",
      "NameError: name 'tokens_filtered_top' is not defined\n",
      "\n",
      "During handling of the above exception, another exception occurred:\n",
      "\n",
      "Traceback (most recent call last):\n",
      "  File \"c:\\Users\\azhur\\AppData\\Local\\Programs\\Python\\Python310\\lib\\site-packages\\IPython\\core\\interactiveshell.py\", line 1993, in showtraceback\n",
      "    stb = self.InteractiveTB.structured_traceback(\n",
      "  File \"c:\\Users\\azhur\\AppData\\Local\\Programs\\Python\\Python310\\lib\\site-packages\\IPython\\core\\ultratb.py\", line 1118, in structured_traceback\n",
      "    return FormattedTB.structured_traceback(\n",
      "  File \"c:\\Users\\azhur\\AppData\\Local\\Programs\\Python\\Python310\\lib\\site-packages\\IPython\\core\\ultratb.py\", line 1012, in structured_traceback\n",
      "    return VerboseTB.structured_traceback(\n",
      "  File \"c:\\Users\\azhur\\AppData\\Local\\Programs\\Python\\Python310\\lib\\site-packages\\IPython\\core\\ultratb.py\", line 865, in structured_traceback\n",
      "    formatted_exception = self.format_exception_as_a_whole(etype, evalue, etb, number_of_lines_of_context,\n",
      "  File \"c:\\Users\\azhur\\AppData\\Local\\Programs\\Python\\Python310\\lib\\site-packages\\IPython\\core\\ultratb.py\", line 799, in format_exception_as_a_whole\n",
      "    self.get_records(etb, number_of_lines_of_context, tb_offset) if etb else []\n",
      "  File \"c:\\Users\\azhur\\AppData\\Local\\Programs\\Python\\Python310\\lib\\site-packages\\IPython\\core\\ultratb.py\", line 845, in get_records\n",
      "    style = stack_data.style_with_executing_node(style, \"bg:ansiyellow\")\n",
      "  File \"c:\\Users\\azhur\\AppData\\Local\\Programs\\Python\\Python310\\lib\\site-packages\\stack_data\\core.py\", line 424, in style_with_executing_node\n",
      "    class NewStyle(style):\n",
      "  File \"c:\\Users\\azhur\\AppData\\Local\\Programs\\Python\\Python310\\lib\\site-packages\\pygments\\style.py\", line 91, in __new__\n",
      "    ndef[4] = colorformat(styledef[3:])\n",
      "  File \"c:\\Users\\azhur\\AppData\\Local\\Programs\\Python\\Python310\\lib\\site-packages\\pygments\\style.py\", line 58, in colorformat\n",
      "    assert False, \"wrong color format %r\" % text\n",
      "AssertionError: wrong color format 'ansiyellow'\n"
     ]
    }
   ],
   "source": [
    "tokens_filtered_top[:10]"
   ]
  },
  {
   "cell_type": "code",
   "execution_count": 22,
   "metadata": {},
   "outputs": [
    {
     "name": "stdout",
     "output_type": "stream",
     "text": [
      "Unexpected exception formatting exception. Falling back to standard exception\n"
     ]
    },
    {
     "name": "stderr",
     "output_type": "stream",
     "text": [
      "Traceback (most recent call last):\n",
      "  File \"c:\\Users\\azhur\\AppData\\Local\\Programs\\Python\\Python310\\lib\\site-packages\\IPython\\core\\interactiveshell.py\", line 3398, in run_code\n",
      "    exec(code_obj, self.user_global_ns, self.user_ns)\n",
      "  File \"C:\\Users\\azhur\\AppData\\Local\\Temp\\ipykernel_34128\\917926469.py\", line 1, in <cell line: 1>\n",
      "    vocabulary = {v: k for k, v in dict(enumerate(tokens_filtered_top, 1)).items()}\n",
      "NameError: name 'tokens_filtered_top' is not defined\n",
      "\n",
      "During handling of the above exception, another exception occurred:\n",
      "\n",
      "Traceback (most recent call last):\n",
      "  File \"c:\\Users\\azhur\\AppData\\Local\\Programs\\Python\\Python310\\lib\\site-packages\\IPython\\core\\interactiveshell.py\", line 1993, in showtraceback\n",
      "    stb = self.InteractiveTB.structured_traceback(\n",
      "  File \"c:\\Users\\azhur\\AppData\\Local\\Programs\\Python\\Python310\\lib\\site-packages\\IPython\\core\\ultratb.py\", line 1118, in structured_traceback\n",
      "    return FormattedTB.structured_traceback(\n",
      "  File \"c:\\Users\\azhur\\AppData\\Local\\Programs\\Python\\Python310\\lib\\site-packages\\IPython\\core\\ultratb.py\", line 1012, in structured_traceback\n",
      "    return VerboseTB.structured_traceback(\n",
      "  File \"c:\\Users\\azhur\\AppData\\Local\\Programs\\Python\\Python310\\lib\\site-packages\\IPython\\core\\ultratb.py\", line 865, in structured_traceback\n",
      "    formatted_exception = self.format_exception_as_a_whole(etype, evalue, etb, number_of_lines_of_context,\n",
      "  File \"c:\\Users\\azhur\\AppData\\Local\\Programs\\Python\\Python310\\lib\\site-packages\\IPython\\core\\ultratb.py\", line 799, in format_exception_as_a_whole\n",
      "    self.get_records(etb, number_of_lines_of_context, tb_offset) if etb else []\n",
      "  File \"c:\\Users\\azhur\\AppData\\Local\\Programs\\Python\\Python310\\lib\\site-packages\\IPython\\core\\ultratb.py\", line 845, in get_records\n",
      "    style = stack_data.style_with_executing_node(style, \"bg:ansiyellow\")\n",
      "  File \"c:\\Users\\azhur\\AppData\\Local\\Programs\\Python\\Python310\\lib\\site-packages\\stack_data\\core.py\", line 424, in style_with_executing_node\n",
      "    class NewStyle(style):\n",
      "  File \"c:\\Users\\azhur\\AppData\\Local\\Programs\\Python\\Python310\\lib\\site-packages\\pygments\\style.py\", line 91, in __new__\n",
      "    ndef[4] = colorformat(styledef[3:])\n",
      "  File \"c:\\Users\\azhur\\AppData\\Local\\Programs\\Python\\Python310\\lib\\site-packages\\pygments\\style.py\", line 58, in colorformat\n",
      "    assert False, \"wrong color format %r\" % text\n",
      "AssertionError: wrong color format 'ansiyellow'\n"
     ]
    }
   ],
   "source": [
    "vocabulary = {v: k for k, v in dict(enumerate(tokens_filtered_top, 1)).items()}\n",
    "# vocabulary"
   ]
  },
  {
   "cell_type": "code",
   "execution_count": 23,
   "metadata": {},
   "outputs": [],
   "source": [
    "import numpy as np\n",
    "\n",
    "\n",
    "def text_to_sequence(text, maxlen):\n",
    "    result = []\n",
    "    tokens = word_tokenize(text.lower())\n",
    "    tokens_filtered = [word for word in tokens if word.isalnum()]\n",
    "    for word in tokens_filtered:\n",
    "        if word in vocabulary:\n",
    "            result.append(vocabulary[word])\n",
    "\n",
    "    padding = [0] * (maxlen-len(result))\n",
    "    return result[-maxlen:] + padding"
   ]
  },
  {
   "cell_type": "code",
   "execution_count": 24,
   "metadata": {},
   "outputs": [
    {
     "name": "stdout",
     "output_type": "stream",
     "text": [
      "Unexpected exception formatting exception. Falling back to standard exception\n"
     ]
    },
    {
     "name": "stderr",
     "output_type": "stream",
     "text": [
      "Traceback (most recent call last):\n",
      "  File \"c:\\Users\\azhur\\AppData\\Local\\Programs\\Python\\Python310\\lib\\site-packages\\IPython\\core\\interactiveshell.py\", line 3398, in run_code\n",
      "    exec(code_obj, self.user_global_ns, self.user_ns)\n",
      "  File \"C:\\Users\\azhur\\AppData\\Local\\Temp\\ipykernel_34128\\2814689960.py\", line 1, in <cell line: 1>\n",
      "    x_train = np.asarray([text_to_sequence(text, max_len) for text in df_train[\"text\"]], dtype=np.int32)\n",
      "NameError: name 'df_train' is not defined\n",
      "\n",
      "During handling of the above exception, another exception occurred:\n",
      "\n",
      "Traceback (most recent call last):\n",
      "  File \"c:\\Users\\azhur\\AppData\\Local\\Programs\\Python\\Python310\\lib\\site-packages\\IPython\\core\\interactiveshell.py\", line 1993, in showtraceback\n",
      "    stb = self.InteractiveTB.structured_traceback(\n",
      "  File \"c:\\Users\\azhur\\AppData\\Local\\Programs\\Python\\Python310\\lib\\site-packages\\IPython\\core\\ultratb.py\", line 1118, in structured_traceback\n",
      "    return FormattedTB.structured_traceback(\n",
      "  File \"c:\\Users\\azhur\\AppData\\Local\\Programs\\Python\\Python310\\lib\\site-packages\\IPython\\core\\ultratb.py\", line 1012, in structured_traceback\n",
      "    return VerboseTB.structured_traceback(\n",
      "  File \"c:\\Users\\azhur\\AppData\\Local\\Programs\\Python\\Python310\\lib\\site-packages\\IPython\\core\\ultratb.py\", line 865, in structured_traceback\n",
      "    formatted_exception = self.format_exception_as_a_whole(etype, evalue, etb, number_of_lines_of_context,\n",
      "  File \"c:\\Users\\azhur\\AppData\\Local\\Programs\\Python\\Python310\\lib\\site-packages\\IPython\\core\\ultratb.py\", line 799, in format_exception_as_a_whole\n",
      "    self.get_records(etb, number_of_lines_of_context, tb_offset) if etb else []\n",
      "  File \"c:\\Users\\azhur\\AppData\\Local\\Programs\\Python\\Python310\\lib\\site-packages\\IPython\\core\\ultratb.py\", line 845, in get_records\n",
      "    style = stack_data.style_with_executing_node(style, \"bg:ansiyellow\")\n",
      "  File \"c:\\Users\\azhur\\AppData\\Local\\Programs\\Python\\Python310\\lib\\site-packages\\stack_data\\core.py\", line 424, in style_with_executing_node\n",
      "    class NewStyle(style):\n",
      "  File \"c:\\Users\\azhur\\AppData\\Local\\Programs\\Python\\Python310\\lib\\site-packages\\pygments\\style.py\", line 91, in __new__\n",
      "    ndef[4] = colorformat(styledef[3:])\n",
      "  File \"c:\\Users\\azhur\\AppData\\Local\\Programs\\Python\\Python310\\lib\\site-packages\\pygments\\style.py\", line 58, in colorformat\n",
      "    assert False, \"wrong color format %r\" % text\n",
      "AssertionError: wrong color format 'ansiyellow'\n"
     ]
    }
   ],
   "source": [
    "x_train = np.asarray([text_to_sequence(text, max_len) for text in df_train[\"text\"]], dtype=np.int32)\n",
    "x_val = np.asarray([text_to_sequence(text, max_len) for text in df_val[\"text\"]], dtype=np.int32)"
   ]
  },
  {
   "cell_type": "code",
   "execution_count": 25,
   "metadata": {},
   "outputs": [
    {
     "name": "stdout",
     "output_type": "stream",
     "text": [
      "Unexpected exception formatting exception. Falling back to standard exception\n"
     ]
    },
    {
     "name": "stderr",
     "output_type": "stream",
     "text": [
      "Traceback (most recent call last):\n",
      "  File \"c:\\Users\\azhur\\AppData\\Local\\Programs\\Python\\Python310\\lib\\site-packages\\IPython\\core\\interactiveshell.py\", line 3398, in run_code\n",
      "    exec(code_obj, self.user_global_ns, self.user_ns)\n",
      "  File \"C:\\Users\\azhur\\AppData\\Local\\Temp\\ipykernel_34128\\2512218947.py\", line 1, in <cell line: 1>\n",
      "    x_train.shape\n",
      "NameError: name 'x_train' is not defined\n",
      "\n",
      "During handling of the above exception, another exception occurred:\n",
      "\n",
      "Traceback (most recent call last):\n",
      "  File \"c:\\Users\\azhur\\AppData\\Local\\Programs\\Python\\Python310\\lib\\site-packages\\IPython\\core\\interactiveshell.py\", line 1993, in showtraceback\n",
      "    stb = self.InteractiveTB.structured_traceback(\n",
      "  File \"c:\\Users\\azhur\\AppData\\Local\\Programs\\Python\\Python310\\lib\\site-packages\\IPython\\core\\ultratb.py\", line 1118, in structured_traceback\n",
      "    return FormattedTB.structured_traceback(\n",
      "  File \"c:\\Users\\azhur\\AppData\\Local\\Programs\\Python\\Python310\\lib\\site-packages\\IPython\\core\\ultratb.py\", line 1012, in structured_traceback\n",
      "    return VerboseTB.structured_traceback(\n",
      "  File \"c:\\Users\\azhur\\AppData\\Local\\Programs\\Python\\Python310\\lib\\site-packages\\IPython\\core\\ultratb.py\", line 865, in structured_traceback\n",
      "    formatted_exception = self.format_exception_as_a_whole(etype, evalue, etb, number_of_lines_of_context,\n",
      "  File \"c:\\Users\\azhur\\AppData\\Local\\Programs\\Python\\Python310\\lib\\site-packages\\IPython\\core\\ultratb.py\", line 799, in format_exception_as_a_whole\n",
      "    self.get_records(etb, number_of_lines_of_context, tb_offset) if etb else []\n",
      "  File \"c:\\Users\\azhur\\AppData\\Local\\Programs\\Python\\Python310\\lib\\site-packages\\IPython\\core\\ultratb.py\", line 845, in get_records\n",
      "    style = stack_data.style_with_executing_node(style, \"bg:ansiyellow\")\n",
      "  File \"c:\\Users\\azhur\\AppData\\Local\\Programs\\Python\\Python310\\lib\\site-packages\\stack_data\\core.py\", line 424, in style_with_executing_node\n",
      "    class NewStyle(style):\n",
      "  File \"c:\\Users\\azhur\\AppData\\Local\\Programs\\Python\\Python310\\lib\\site-packages\\pygments\\style.py\", line 91, in __new__\n",
      "    ndef[4] = colorformat(styledef[3:])\n",
      "  File \"c:\\Users\\azhur\\AppData\\Local\\Programs\\Python\\Python310\\lib\\site-packages\\pygments\\style.py\", line 58, in colorformat\n",
      "    assert False, \"wrong color format %r\" % text\n",
      "AssertionError: wrong color format 'ansiyellow'\n"
     ]
    }
   ],
   "source": [
    "x_train.shape"
   ]
  },
  {
   "cell_type": "code",
   "execution_count": 26,
   "metadata": {},
   "outputs": [
    {
     "name": "stdout",
     "output_type": "stream",
     "text": [
      "Unexpected exception formatting exception. Falling back to standard exception\n"
     ]
    },
    {
     "name": "stderr",
     "output_type": "stream",
     "text": [
      "Traceback (most recent call last):\n",
      "  File \"c:\\Users\\azhur\\AppData\\Local\\Programs\\Python\\Python310\\lib\\site-packages\\IPython\\core\\interactiveshell.py\", line 3398, in run_code\n",
      "    exec(code_obj, self.user_global_ns, self.user_ns)\n",
      "  File \"C:\\Users\\azhur\\AppData\\Local\\Temp\\ipykernel_34128\\2845096818.py\", line 1, in <cell line: 1>\n",
      "    x_train[1]\n",
      "NameError: name 'x_train' is not defined\n",
      "\n",
      "During handling of the above exception, another exception occurred:\n",
      "\n",
      "Traceback (most recent call last):\n",
      "  File \"c:\\Users\\azhur\\AppData\\Local\\Programs\\Python\\Python310\\lib\\site-packages\\IPython\\core\\interactiveshell.py\", line 1993, in showtraceback\n",
      "    stb = self.InteractiveTB.structured_traceback(\n",
      "  File \"c:\\Users\\azhur\\AppData\\Local\\Programs\\Python\\Python310\\lib\\site-packages\\IPython\\core\\ultratb.py\", line 1118, in structured_traceback\n",
      "    return FormattedTB.structured_traceback(\n",
      "  File \"c:\\Users\\azhur\\AppData\\Local\\Programs\\Python\\Python310\\lib\\site-packages\\IPython\\core\\ultratb.py\", line 1012, in structured_traceback\n",
      "    return VerboseTB.structured_traceback(\n",
      "  File \"c:\\Users\\azhur\\AppData\\Local\\Programs\\Python\\Python310\\lib\\site-packages\\IPython\\core\\ultratb.py\", line 865, in structured_traceback\n",
      "    formatted_exception = self.format_exception_as_a_whole(etype, evalue, etb, number_of_lines_of_context,\n",
      "  File \"c:\\Users\\azhur\\AppData\\Local\\Programs\\Python\\Python310\\lib\\site-packages\\IPython\\core\\ultratb.py\", line 799, in format_exception_as_a_whole\n",
      "    self.get_records(etb, number_of_lines_of_context, tb_offset) if etb else []\n",
      "  File \"c:\\Users\\azhur\\AppData\\Local\\Programs\\Python\\Python310\\lib\\site-packages\\IPython\\core\\ultratb.py\", line 845, in get_records\n",
      "    style = stack_data.style_with_executing_node(style, \"bg:ansiyellow\")\n",
      "  File \"c:\\Users\\azhur\\AppData\\Local\\Programs\\Python\\Python310\\lib\\site-packages\\stack_data\\core.py\", line 424, in style_with_executing_node\n",
      "    class NewStyle(style):\n",
      "  File \"c:\\Users\\azhur\\AppData\\Local\\Programs\\Python\\Python310\\lib\\site-packages\\pygments\\style.py\", line 91, in __new__\n",
      "    ndef[4] = colorformat(styledef[3:])\n",
      "  File \"c:\\Users\\azhur\\AppData\\Local\\Programs\\Python\\Python310\\lib\\site-packages\\pygments\\style.py\", line 58, in colorformat\n",
      "    assert False, \"wrong color format %r\" % text\n",
      "AssertionError: wrong color format 'ansiyellow'\n"
     ]
    }
   ],
   "source": [
    "x_train[1]"
   ]
  },
  {
   "cell_type": "code",
   "execution_count": 27,
   "metadata": {},
   "outputs": [],
   "source": [
    "from torch.utils.data import DataLoader, Dataset\n",
    "import torch\n",
    "\n",
    "\n",
    "class DataWrapper(Dataset):\n",
    "    def __init__(self, data, target, transform=None):\n",
    "        self.data = torch.from_numpy(data).long()\n",
    "        self.target = torch.from_numpy(target).long()\n",
    "        self.transform = transform\n",
    "        \n",
    "    def __getitem__(self, index):\n",
    "        x = self.data[index]\n",
    "        y = self.target[index]\n",
    "        \n",
    "        if self.transform:\n",
    "            x = self.transform(x)\n",
    "            \n",
    "        return x, y\n",
    "    \n",
    "    def __len__(self):\n",
    "        return len(self.data)"
   ]
  },
  {
   "cell_type": "code",
   "execution_count": 28,
   "metadata": {},
   "outputs": [],
   "source": [
    "from torch import nn\n",
    "\n",
    "\n",
    "class RNNFixedLen(nn.Module) :\n",
    "    def __init__(self, vocab_size, embedding_dim=128, hidden_dim=128, use_last=True):\n",
    "        super().__init__()\n",
    "        self.use_last = use_last\n",
    "        self.embeddings = nn.Embedding(vocab_size, embedding_dim, padding_idx=0)\n",
    "        self.rnn = nn.RNN(embedding_dim, hidden_dim, num_layers=2, batch_first=True, )\n",
    "        self.linear = nn.Linear(hidden_dim, 1)\n",
    "        self.dropout = nn.Dropout(0.2)\n",
    "        \n",
    "    def forward(self, x):\n",
    "        x = self.embeddings(x)\n",
    "        x = self.dropout(x)\n",
    "\n",
    "        rnn_out, ht = self.rnn(x) \n",
    "        # rnn_out: тензор с выходными фичами с последнего слоя для каждого t\n",
    "        # h_t: тензор с последними скрытыми состояниями по слоям\n",
    "\n",
    "        if self.use_last:\n",
    "            last_tensor = rnn_out[:,-1,:]\n",
    "        else:\n",
    "            # use mean\n",
    "            last_tensor = torch.mean(rnn_out[:,:], dim=1)\n",
    "    \n",
    "        out = self.linear(last_tensor)\n",
    "        \n",
    "        return torch.sigmoid(out)"
   ]
  },
  {
   "cell_type": "code",
   "execution_count": 29,
   "metadata": {},
   "outputs": [
    {
     "name": "stderr",
     "output_type": "stream",
     "text": [
      "c:\\Users\\azhur\\AppData\\Local\\Programs\\Python\\Python310\\lib\\site-packages\\torch\\nn\\modules\\sparse.py:141: UserWarning: Failed to initialize NumPy: module compiled against API version 0x10 but this version of numpy is 0xf (Triggered internally at ..\\torch\\csrc\\utils\\tensor_numpy.cpp:77.)\n",
      "  self.weight = Parameter(torch.empty((num_embeddings, embedding_dim), **factory_kwargs))\n"
     ]
    }
   ],
   "source": [
    "rnn_init = RNNFixedLen(max_words, 128, 20, use_last=False)\n",
    "optimizer = torch.optim.Adam(rnn_init.parameters(), lr=0.001)\n",
    "criterion = nn.BCELoss()"
   ]
  },
  {
   "cell_type": "code",
   "execution_count": 30,
   "metadata": {},
   "outputs": [
    {
     "name": "stdout",
     "output_type": "stream",
     "text": [
      "RNNFixedLen(\n",
      "  (embeddings): Embedding(2000, 128, padding_idx=0)\n",
      "  (rnn): RNN(128, 20, num_layers=2, batch_first=True)\n",
      "  (linear): Linear(in_features=20, out_features=1, bias=True)\n",
      "  (dropout): Dropout(p=0.2, inplace=False)\n",
      ")\n",
      "Parameters: 259861\n"
     ]
    }
   ],
   "source": [
    "print(rnn_init)\n",
    "print(\"Parameters:\", sum([param.nelement() for param in rnn_init.parameters()]))"
   ]
  },
  {
   "cell_type": "code",
   "execution_count": 31,
   "metadata": {},
   "outputs": [
    {
     "data": {
      "text/plain": [
       "'cpu'"
      ]
     },
     "execution_count": 31,
     "metadata": {},
     "output_type": "execute_result"
    }
   ],
   "source": [
    "device = 'cuda' if torch.cuda.is_available() else 'cpu'\n",
    "rnn_init.to(device)\n",
    "device"
   ]
  },
  {
   "cell_type": "code",
   "execution_count": 32,
   "metadata": {},
   "outputs": [
    {
     "name": "stdout",
     "output_type": "stream",
     "text": [
      "Unexpected exception formatting exception. Falling back to standard exception\n"
     ]
    },
    {
     "name": "stderr",
     "output_type": "stream",
     "text": [
      "Traceback (most recent call last):\n",
      "  File \"c:\\Users\\azhur\\AppData\\Local\\Programs\\Python\\Python310\\lib\\site-packages\\IPython\\core\\interactiveshell.py\", line 3398, in run_code\n",
      "    exec(code_obj, self.user_global_ns, self.user_ns)\n",
      "  File \"C:\\Users\\azhur\\AppData\\Local\\Temp\\ipykernel_34128\\1699438429.py\", line 12, in <cell line: 9>\n",
      "    for i, data in enumerate(train_loader):\n",
      "NameError: name 'train_loader' is not defined\n",
      "\n",
      "During handling of the above exception, another exception occurred:\n",
      "\n",
      "Traceback (most recent call last):\n",
      "  File \"c:\\Users\\azhur\\AppData\\Local\\Programs\\Python\\Python310\\lib\\site-packages\\IPython\\core\\interactiveshell.py\", line 1993, in showtraceback\n",
      "    stb = self.InteractiveTB.structured_traceback(\n",
      "  File \"c:\\Users\\azhur\\AppData\\Local\\Programs\\Python\\Python310\\lib\\site-packages\\IPython\\core\\ultratb.py\", line 1118, in structured_traceback\n",
      "    return FormattedTB.structured_traceback(\n",
      "  File \"c:\\Users\\azhur\\AppData\\Local\\Programs\\Python\\Python310\\lib\\site-packages\\IPython\\core\\ultratb.py\", line 1012, in structured_traceback\n",
      "    return VerboseTB.structured_traceback(\n",
      "  File \"c:\\Users\\azhur\\AppData\\Local\\Programs\\Python\\Python310\\lib\\site-packages\\IPython\\core\\ultratb.py\", line 865, in structured_traceback\n",
      "    formatted_exception = self.format_exception_as_a_whole(etype, evalue, etb, number_of_lines_of_context,\n",
      "  File \"c:\\Users\\azhur\\AppData\\Local\\Programs\\Python\\Python310\\lib\\site-packages\\IPython\\core\\ultratb.py\", line 799, in format_exception_as_a_whole\n",
      "    self.get_records(etb, number_of_lines_of_context, tb_offset) if etb else []\n",
      "  File \"c:\\Users\\azhur\\AppData\\Local\\Programs\\Python\\Python310\\lib\\site-packages\\IPython\\core\\ultratb.py\", line 845, in get_records\n",
      "    style = stack_data.style_with_executing_node(style, \"bg:ansiyellow\")\n",
      "  File \"c:\\Users\\azhur\\AppData\\Local\\Programs\\Python\\Python310\\lib\\site-packages\\stack_data\\core.py\", line 424, in style_with_executing_node\n",
      "    class NewStyle(style):\n",
      "  File \"c:\\Users\\azhur\\AppData\\Local\\Programs\\Python\\Python310\\lib\\site-packages\\pygments\\style.py\", line 91, in __new__\n",
      "    ndef[4] = colorformat(styledef[3:])\n",
      "  File \"c:\\Users\\azhur\\AppData\\Local\\Programs\\Python\\Python310\\lib\\site-packages\\pygments\\style.py\", line 58, in colorformat\n",
      "    assert False, \"wrong color format %r\" % text\n",
      "AssertionError: wrong color format 'ansiyellow'\n"
     ]
    }
   ],
   "source": [
    "rnn_init = rnn_init.to(device)\n",
    "rnn_init.train()\n",
    "th = 0.5\n",
    "\n",
    "train_loss_history = []\n",
    "test_loss_history = []\n",
    "\n",
    "\n",
    "for epoch in range(epochs):  \n",
    "    rnn_init.train()\n",
    "    running_items, running_right = 0.0, 0.0\n",
    "    for i, data in enumerate(train_loader):\n",
    "        inputs, labels = data[0].to(device), data[1].to(device)\n",
    "\n",
    "        # обнуляем градиент\n",
    "        optimizer.zero_grad()\n",
    "        outputs = rnn_init(inputs)\n",
    "        \n",
    "        loss = criterion(outputs, labels.float().view(-1, 1))\n",
    "        loss.backward()\n",
    "        optimizer.step()\n",
    "\n",
    "        # подсчет ошибки на обучении\n",
    "        loss = loss.item()\n",
    "        running_items += len(labels)\n",
    "        # подсчет метрики на обучении\n",
    "        pred_labels = torch.squeeze((outputs > th).int())\n",
    "        running_right += (labels == pred_labels).sum()\n",
    "        \n",
    "    # выводим статистику о процессе обучения\n",
    "    rnn_init.eval()\n",
    "    \n",
    "    print(f'Epoch [{epoch + 1}/{epochs}]. ' \\\n",
    "          f'Step [{i + 1}/{len(train_loader)}]. ' \\\n",
    "          f'Loss: {loss:.3f}. ' \\\n",
    "          f'Acc: {running_right / running_items:.3f}', end='. ')\n",
    "    running_loss, running_items, running_right = 0.0, 0.0, 0.0\n",
    "    train_loss_history.append(loss)\n",
    "\n",
    "    # выводим статистику на тестовых данных\n",
    "    test_running_right, test_running_total, test_loss = 0.0, 0.0, 0.0\n",
    "    for j, data in enumerate(val_loader):\n",
    "        test_labels = data[1].to(device)\n",
    "        test_outputs = rnn_init(data[0].to(device))\n",
    "        \n",
    "        # подсчет ошибки на тесте\n",
    "        test_loss = criterion(test_outputs, test_labels.float().view(-1, 1))\n",
    "        # подсчет метрики на тесте\n",
    "        test_running_total += len(data[1])\n",
    "        pred_test_labels = torch.squeeze((test_outputs > th).int())\n",
    "        test_running_right += (test_labels == pred_test_labels).sum()\n",
    "    \n",
    "    test_loss_history.append(test_loss.item())\n",
    "    print(f'Test loss: {test_loss:.3f}. Test acc: {test_running_right / test_running_total:.3f}')\n",
    "        \n",
    "print('Training is finished!')"
   ]
  },
  {
   "cell_type": "code",
   "execution_count": null,
   "metadata": {},
   "outputs": [],
   "source": []
  }
 ],
 "metadata": {
  "kernelspec": {
   "display_name": "Python 3",
   "language": "python",
   "name": "python3"
  },
  "language_info": {
   "codemirror_mode": {
    "name": "ipython",
    "version": 3
   },
   "file_extension": ".py",
   "mimetype": "text/x-python",
   "name": "python",
   "nbconvert_exporter": "python",
   "pygments_lexer": "ipython3",
   "version": "3.10.2"
  },
  "orig_nbformat": 4
 },
 "nbformat": 4,
 "nbformat_minor": 2
}
